Workbook
Name converterReport.php?loco_4528_date_2020_07_21: Sheet1!#REF!
Name ExternalData_1: Sheet1!#REF!
Name ExternalData_1: Sheet2!#REF!
Name ExternalData_1: Sheet3!#REF!
Name ExternalData_10: Sheet1!#REF!
Name ExternalData_10: Sheet2!#REF!
Name ExternalData_10: Sheet3!#REF!
Name ExternalData_100: Sheet1!#REF!
Name ExternalData_100: Sheet2!#REF!
Name ExternalData_100: Sheet3!#REF!
Name ExternalData_1000: Sheet1!#REF!
Name ExternalData_1000: Sheet2!#REF!
Name ExternalData_1000: Sheet3!#REF!
Name ExternalData_1001: Sheet1!#REF!
Name ExternalData_1001: Sheet2!#REF!
Name ExternalData_1001: Sheet3!#REF!
Name ExternalData_1002: Sheet1!#REF!
Name ExternalData_1002: Sheet2!#REF!
Name ExternalData_1002: Sheet3!#REF!
Name ExternalData_1003: Sheet1!#REF!
Name ExternalData_1003: Sheet2!#REF!
Name ExternalData_1003: Sheet3!#REF!
Name ExternalData_1004: Sheet1!#REF!
Name ExternalData_1004: Sheet2!#REF!
Name ExternalData_1004: Sheet3!#REF!
Name ExternalData_1005: Sheet1!#REF!
Name ExternalData_1005: Sheet2!#REF!
Name ExternalData_1005: Sheet3!#REF!
Name ExternalData_1006: Sheet1!#REF!
Name ExternalData_1006: Sheet2!#REF!
Name ExternalData_1006: Sheet3!#REF!
Name ExternalData_1007: Sheet1!#REF!
Name ExternalData_1007: Sheet2!#REF!
Name ExternalData_1007: Sheet3!#REF!
Name ExternalData_1008: Sheet1!#REF!
Name ExternalData_1008: Sheet2!#REF!
Name ExternalData_1008: Sheet3!#REF!
Name ExternalData_1009: Sheet1!#REF!
Name ExternalData_1009: Sheet2!#REF!
Name ExternalData_1009: Sheet3!#REF!
Name ExternalData_101: Sheet1!#REF!
Name ExternalData_101: Sheet2!#REF!
Name ExternalData_101: Sheet3!#REF!
Name ExternalData_1010: Sheet1!#REF!
Name ExternalData_1010: Sheet2!#REF!
Name ExternalData_1010: Sheet3!#REF!
Name ExternalData_1011: Sheet1!#REF!
Name ExternalData_1011: Sheet2!#REF!
Name ExternalData_1011: Sheet3!#REF!
Name ExternalData_1012: Sheet1!#REF!
Name ExternalData_1012: Sheet2!#REF!
Name ExternalData_1012: Sheet3!#REF!
Name ExternalData_1013: Sheet1!#REF!
Name ExternalData_1013: Sheet2!#REF!
Name ExternalData_1013: Sheet3!#REF!
Name ExternalData_1014: Sheet1!#REF!
Name ExternalData_1014: Sheet2!#REF!
Name ExternalData_1014: Sheet3!#REF!
Name ExternalData_1015: Sheet1!#REF!
Name ExternalData_1015: Sheet2!#REF!

Sheet Sheet1
A1: Vehicle | B1: Converter 1_x000D_ (° F) | C1: Converter 2_x000D_ (° F)

Sheet Sheet2
A1: Vehicle | B1: Converter 1_x000D_ (° F) | C1: Converter 2_x000D_ (° F)

Sheet Sheet3
A1: Vehicle | B1: Converter 1_x000D_ (° F) | C1: Converter 2_x000D_ (° F) | DB1: Vehicle | DC1: Converter 1_x000D_ (° F) | DD1: Converter 2_x000D_ (° F)

Sheet Sheet4
A1: Vehicle | B1: Converter 1_x000D_ (° F) | C1: Converter 2_x000D_ (° F)

Sheet ALP TEMPS
A1: ALP-45DP | D1: Converter Temperature Report for: | M1: =NOW() -> 46241.277
A2: VEHICLE | B2: CONVERTER 1 (°F) | C2: CONVERTER 2 (°F)
A3: =Sheet1!A2 -> 0 | B3: =IF(Sheet1!B2 > 0, Sheet1!B2, "NOT REPORTING") -> NOT REPORTING | C3: =IF(Sheet1!C2 > 0, Sheet1!C2, "NOT REPORTING") -> NOT REPORTING | S3: 138 | V3: 4500 | W3: 138 | X3: 143
A4: =Sheet1!A3 -> 0 | B4: =IF(Sheet1!B3 > 0, Sheet1!B3, "NOT REPORTING") -> NOT REPORTING | C4: =IF(Sheet1!C3 > 0, Sheet1!C3, "NOT REPORTING") -> NOT REPORTING | V4: 4501 | W4: 138 | X4: 143
A5: =Sheet1!A4 -> 0 | B5: =IF(Sheet1!B4 > 0, Sheet1!B4, "NOT REPORTING") -> NOT REPORTING | C5: =IF(Sheet1!C4 > 0, Sheet1!C4, "NOT REPORTING") -> NOT REPORTING | V5: 4502 | W5: 138 | X5: 143
A6: =Sheet1!A5 -> 0 | B6: =IF(Sheet1!B5 > 0, Sheet1!B5, "NOT REPORTING") -> NOT REPORTING | C6: =IF(Sheet1!C5 > 0, Sheet1!C5, "NOT REPORTING") -> NOT REPORTING | V6: 4503 | W6: 138 | X6: 143
A7: =Sheet1!A6 -> 0 | B7: =IF(Sheet1!B6 > 0, Sheet1!B6, "NOT REPORTING") -> NOT REPORTING | C7: =IF(Sheet1!C6 > 0, Sheet1!C6, "NOT REPORTING") -> NOT REPORTING | V7: 4504 | W7: 138 | X7: 143
A8: =Sheet1!A7 -> 0 | B8: =IF(Sheet1!B7 > 0, Sheet1!B7, "NOT REPORTING") -> NOT REPORTING | C8: =IF(Sheet1!C7 > 0, Sheet1!C7, "NOT REPORTING") -> NOT REPORTING | V8: 4505 | W8: 138 | X8: 143
A9: =Sheet1!A8 -> 0 | B9: =IF(Sheet1!B8 > 0, Sheet1!B8, "NOT REPORTING") -> NOT REPORTING | C9: =IF(Sheet1!C8 > 0, Sheet1!C8, "NOT REPORTING") -> NOT REPORTING | V9: 4506 | W9: 138 | X9: 143
A10: =Sheet1!A9 -> 0 | B10: =IF(Sheet1!B9 > 0, Sheet1!B9, "NOT REPORTING") -> NOT REPORTING | C10: =IF(Sheet1!C9 > 0, Sheet1!C9, "NOT REPORTING") -> NOT REPORTING | V10: 4507 | W10: 138 | X10: 143
A11: =Sheet1!A10 -> 0 | B11: =IF(Sheet1!B10 > 0, Sheet1!B10, "NOT REPORTING") -> NOT REPORTING | C11: =IF(Sheet1!C10 > 0, Sheet1!C10, "NOT REPORTING") -> NOT REPORTING | V11: 4508 | W11: 138 | X11: 143
A12: =Sheet1!A11 -> 0 | B12: =IF(Sheet1!B11 > 0, Sheet1!B11, "NOT REPORTING") -> NOT REPORTING | C12: =IF(Sheet1!C11 > 0, Sheet1!C11, "NOT REPORTING") -> NOT REPORTING | V12: 4509 | W12: 138 | X12: 143
A13: =Sheet1!A12 -> 0 | B13: =IF(Sheet1!B12 > 0, Sheet1!B12, "NOT REPORTING") -> NOT REPORTING | C13: =IF(Sheet1!C12 > 0, Sheet1!C12, "NOT REPORTING") -> NOT REPORTING | V13: 4510 | W13: 138 | X13: 143
A14: =Sheet1!A13 -> 0 | B14: =IF(Sheet1!B13 > 0, Sheet1!B13, "NOT REPORTING") -> NOT REPORTING | C14: =IF(Sheet1!C13 > 0, Sheet1!C13, "NOT REPORTING") -> NOT REPORTING | V14: 4511 | W14: 138 | X14: 143
A15: =Sheet1!A14 -> 0 | B15: =IF(Sheet1!B14 > 0, Sheet1!B14, "NOT REPORTING") -> NOT REPORTING | C15: =IF(Sheet1!C14 > 0, Sheet1!C14, "NOT REPORTING") -> NOT REPORTING | V15: 4512 | W15: 138 | X15: 143
... A26: =Sheet1!A25 -> 0 | B26: =IF(Sheet1!B25 > 0, Sheet1!B25, "NOT REPORTING") -> NOT REPORTING | C26: =IF(Sheet1!C25 > 0, Sheet1!C25, "NOT REPORTING") -> NOT REPORTING | V26: 4523 | W26: 138 | X26: 143
A27: =Sheet1!A26 -> 0 | B27: =IF(Sheet1!B26 > 0, Sheet1!B26, "NOT REPORTING") -> NOT REPORTING | C27: =IF(Sheet1!C26 > 0, Sheet1!C26, "NOT REPORTING") -> NOT REPORTING | D27: NOTE: | V27: 4524 | W27: 138 | X27: 143
A28: =Sheet1!A27 -> 0 | B28: =IF(Sheet1!B27 > 0, Sheet1!B27, "NOT REPORTING") -> NOT REPORTING | C28: =IF(Sheet1!C27 > 0, Sheet1!C27, "NOT REPORTING") -> NOT REPORTING | E28: - VEHICLES LISTED AS "NOT REPORTING" ARE EITHER SHOPPED OR YARDED WITH NO POWER. | V28: 4525 | W28: 138 | X28: 143
A29: =Sheet1!A28 -> 0 | B29: =IF(Sheet1!B28 > 0, Sheet1!B28, "NOT REPORTING") -> NOT REPORTING | C29: =IF(Sheet1!C28 > 0, Sheet1!C28, "NOT REPORTING") -> NOT REPORTING | V29: 4526 | W29: 138 | X29: 143
A30: =Sheet1!A29 -> 0 | B30: =IF(Sheet1!B29 > 0, Sheet1!B29, "NOT REPORTING") -> NOT REPORTING | C30: =IF(Sheet1!C29 > 0, Sheet1!C29, "NOT REPORTING") -> NOT REPORTING | E30: - THE BUTTONS IN THIS SPREADSHEET HAVE BEEN DISABLED FOR THIS REPORT. DO NOT CLICK THEM. | V30: 4527 | W30: 138 | X30: 143
A31: =Sheet1!A30 -> 0 | B31: =IF(Sheet1!B30 > 0, Sheet1!B30, "NOT REPORTING") -> NOT REPORTING | C31: =IF(Sheet1!C30 > 0, Sheet1!C30, "NOT REPORTING") -> NOT REPORTING | V31: 4528 | W31: 138 | X31: 143
A32: =Sheet1!A31 -> 0 | B32: =IF(Sheet1!B31 > 0, Sheet1!B31, "NOT REPORTING") -> NOT REPORTING | C32: =IF(Sheet1!C31 > 0, Sheet1!C31, "NOT REPORTING") -> NOT REPORTING | V32: 4529 | W32: 138 | X32: 143
A33: =Sheet1!A32 -> 0 | B33: =IF(Sheet1!B32 > 0, Sheet1!B32, "NOT REPORTING") -> NOT REPORTING | C33: =IF(Sheet1!C32 > 0, Sheet1!C32, "NOT REPORTING") -> NOT REPORTING | V33: 4530 | W33: 138 | X33: 143
A34: =Sheet1!A33 -> 0 | B34: =IF(Sheet1!B33 > 0, Sheet1!B33, "NOT REPORTING") -> NOT REPORTING | C34: =IF(Sheet1!C33 > 0, Sheet1!C33, "NOT REPORTING") -> NOT REPORTING | V34: 4531 | W34: 138 | X34: 143
A35: =Sheet1!A34 -> 0 | B35: =IF(Sheet1!B34 > 0, Sheet1!B34, "NOT REPORTING") -> NOT REPORTING | C35: =IF(Sheet1!C34 > 0, Sheet1!C34, "NOT REPORTING") -> NOT REPORTING | V35: 4532 | W35: 138 | X35: 143
A36: =Sheet1!A35 -> 0 | B36: =IF(Sheet1!B35 > 0, Sheet1!B35, "NOT REPORTING") -> NOT REPORTING | C36: =IF(Sheet1!C35 > 0, Sheet1!C35, "NOT REPORTING") -> NOT REPORTING | V36: 4533 | W36: 138 | X36: 143
A37: =Sheet1!A36 -> 0 | B37: =IF(Sheet1!B36 > 0, Sheet1!B36, "NOT REPORTING") -> NOT REPORTING | C37: =IF(Sheet1!C36 > 0, Sheet1!C36, "NOT REPORTING") -> NOT REPORTING | V37: 4534 | W37: 138 | X37: 143
A38: ALP-46 | D38: Converter Temperature Report for 08/05/2026 07:52:52 AM
A39: VEHICLE | B39: CONVERTER 1 (°F) | C39: CONVERTER 2 (°F)
A40: =Sheet2!A2 -> 0 | B40: =IF(Sheet2!B2 > 0, Sheet2!B2, "NOT REPORTING") -> NOT REPORTING | C40: =IF(Sheet2!C2 > 0, Sheet2!C2, "NOT REPORTING") -> NOT REPORTING | V40: 4600 | W40: 138 | X40: 143
A41: =Sheet2!A3 -> 0 | B41: =IF(Sheet2!B3 > 0, Sheet2!B3, "NOT REPORTING") -> NOT REPORTING | C41: =IF(Sheet2!C3 > 0, Sheet2!C3, "NOT REPORTING") -> NOT REPORTING | V41: 4601 | W41: 138 | X41: 143
A42: =Sheet2!A4 -> 0 | B42: =IF(Sheet2!B4 > 0, Sheet2!B4, "NOT REPORTING") -> NOT REPORTING | C42: =IF(Sheet2!C4 > 0, Sheet2!C4, "NOT REPORTING") -> NOT REPORTING | V42: 4602 | W42: 138 | X42: 143
A43: =Sheet2!A5 -> 0 | B43: =IF(Sheet2!B5 > 0, Sheet2!B5, "NOT REPORTING") -> NOT REPORTING | C43: =IF(Sheet2!C5 > 0, Sheet2!C5, "NOT REPORTING") -> NOT REPORTING | V43: 4603 | W43: 138 | X43: 143
A44: =Sheet2!A6 -> 0 | B44: =IF(Sheet2!B6 > 0, Sheet2!B6, "NOT REPORTING") -> NOT REPORTING | C44: =IF(Sheet2!C6 > 0, Sheet2!C6, "NOT REPORTING") -> NOT REPORTING | V44: 4604 | W44: 138 | X44: 143
A45: =Sheet2!A7 -> 0 | B45: =IF(Sheet2!B7 > 0, Sheet2!B7, "NOT REPORTING") -> NOT REPORTING | C45: =IF(Sheet2!C7 > 0, Sheet2!C7, "NOT REPORTING") -> NOT REPORTING | V45: 4605 | W45: 138 | X45: 143
A46: =Sheet2!A8 -> 0 | B46: =IF(Sheet2!B8 > 0, Sheet2!B8, "NOT REPORTING") -> NOT REPORTING | C46: =IF(Sheet2!C8 > 0, Sheet2!C8, "NOT REPORTING") -> NOT REPORTING | V46: 4606 | W46: 138 | X46: 143
A47: =Sheet2!A9 -> 0 | B47: =IF(Sheet2!B9 > 0, Sheet2!B9, "NOT REPORTING") -> NOT REPORTING | C47: =IF(Sheet2!C9 > 0, Sheet2!C9, "NOT REPORTING") -> NOT REPORTING | V47: 4607 | W47: 138 | X47: 143
A48: =Sheet2!A10 -> 0 | B48: =IF(Sheet2!B10 > 0, Sheet2!B10, "NOT REPORTING") -> NOT REPORTING | C48: =IF(Sheet2!C10 > 0, Sheet2!C10, "NOT REPORTING") -> NOT REPORTING | V48: 4608 | W48: 138 | X48: 143
A49: =Sheet2!A11 -> 0 | B49: =IF(Sheet2!B11 > 0, Sheet2!B11, "NOT REPORTING") -> NOT REPORTING | C49: =IF(Sheet2!C11 > 0, Sheet2!C11, "NOT REPORTING") -> NOT REPORTING | V49: 4609 | W49: 138 | X49: 143
A50: =Sheet2!A12 -> 0 | B50: =IF(Sheet2!B12 > 0, Sheet2!B12, "NOT REPORTING") -> NOT REPORTING | C50: =IF(Sheet2!C12 > 0, Sheet2!C12, "NOT REPORTING") -> NOT REPORTING | V50: 4610 | W50: 138 | X50: 143
...
